# ☑️ 47\_에러 처리

p.886~892

✍️ 2024.12.20(Fri)

## ✅ 47.1\_에러 처리의 필요성

```jsx
// [에러 처리 X]

console.log("[Start]");

foo(); // ReferenceError: foo is not defined
// 여기서 프로그램 강제 종료

console.log("[End]"); // 실행 X
```

```jsx
// [에러 처리 O (try-catch)]

console.log("[Start]");

try {
  foo();
} catch (error) {
  console.error("[error!!]", error);
} // 에러 대응 -> 프로그램 강제 종료 X

console.log("[End]"); // 실행 O
```

<br/>

## ✅ 47.2_try…catch…finally문

```jsx
try {
  // 실행할 코드 (에러 발생 가능성 있는 코드)
} catch (err) {
  // err는 catch 코드 블록에서만 유효!
  // try 코드 블록에서 에러 발생 -> 이 코드 블록의 코드 실행
  // errr에는 try 코드 블록에서 발생한 Error 객체 전달
} finally {
  // 에러 발생과 상관없이 반드시 1번 실행
} // 강제 종료 X
```

<br/>

## ✅ 47.3_Error 객체

- Error 생성자 함수는 에러 객체를 생성함
  - `message` 프로퍼티: Error 생성자 함수에 인수로 전달한 에러 메시지
  - `stack` 프로퍼티: 에러를 발생시킨 콜스택의 호출 정보를 나타내는 문자열 / 디버깅 목적으로 사용
- Error 생성자 함수에는 에러를 설명하는 에러 메시지를 인수로 전달 가능

```jsx
const error = new Error("invalid");
```

<b>🔔 Error 생성 함수 종류</b>

| 생성자 함수      | 인스턴스                                                             |
| ---------------- | -------------------------------------------------------------------- |
| Error            | 일반적 에러 객체                                                     |
| `SyntaxError`    | JS 문법에 맞지 않는 문 해석시 발생하는 에러 객체                     |
| `ReferenceError` | 참조불가 식별자 참조시 발생하는 에러 객체                            |
| `TypeError`      | 피연산자 / 인수 데이터 타입 유효하지 않을 때 발생하는 에러 객체      |
| `RangeError`     | 숫자값 허용 범위 벗어났을 때 발생하는 에러 객체                      |
| `URIError`       | encodeURI / decodeURI 함수에 부적절한 인수 전달시 발생하는 에러 객체 |
| `EvalError`      | eval 함수에서 발생하는 에러 객체                                     |

```jsx
1 @ 1; // SyntaxError
foo(); // ReferenceError
null.foo; // TypeError
new Array(-1); // RangeError
decodeURIComponent('%'); // URIError
```

<br/>

## ✅ 47.4_throw 문

✋ 에러 객체 생성 ≠ 에러 발생

```jsx
try {
  // 에러 객체 생성 -> 에러가 발생하는건 아님
  new Error("something wrong");
} catch (error) {
  console.log(error);
}
```

👀 에러를 발생시키려면 try 코드 블록에서 throw문으로 에러 객체를 던져야 함

```jsx
try {
  // 에러 객체 던지면 -> catch문의 에러 변수 생성 -> 던져진 에러 객체 할당 -> catch 코드 블록 실행
  throw new Error("something wrong");
} catch (error) {
  console.log(error);
}
```

<br/>

## ✅ 47.5\_에러의 전파

- 에러는 호출자(caller) 방향으로 전파됨 <br/>
  ⇒ 즉, 콜 스택의 아래 방향(실행 중인 실행 컨텍스트가 푸시되기 직전에 푸시된 실행 컨텍스트 방향)으로 전파됨

```jsx
const foo = () => {
  throw Error("foo에서 발생한 에러");
};

const bar = () => {
  foo();
};

const baz = () => {
  bar();
};

try {
  baz();
} catch (err) {
  // baz() -> bar() -> foo() -> 에러 throw -> 호출자에게 전파되어 전역에서 캐치됨
  // 실행 컨텍스트 : foo -> bar -> bax -> 전역 순으로 에러 전파
  console.error(err);
}
```

👀 throw된 에러를 캐치하지 않으면 호출자 방향으로 전파되며, 어디에서도 캐치하지 않으면 프로그램 강제 종료행

✋ 비동기 함수인 setTimeout / 프로미스 후속 처리 메서드의 콜백 함수는 호출자 없음 <br/>
ㄴ why? Queue에 일시 저장되었다가 콜 스택이 비면 이벤트 루프에 의해 콜 스택으로 푸시되어 실행된다. 이때 콜 스택에 푸시된 콜백 함수의 실행 컨텍스트는 콜 스택의 가장 하부에 존재하게 되므로 ⇒ 에러를 전파할 호출자가 존재하지 않음
